<?xml version="1.0" ?>
<robot name="single_joint">
  <gazebo reference="base">
    <material>Gazebo/GrassFloor</material>
  </gazebo>
  <link name="world"/>
  <joint name="link_joint" type="continuous">
    <axis xyz="0 0 1"/>
    <parent link="world"/>
    <origin rpy="0 0 0" xyz="0 0 1"/>
    <child link="link"/>
    <limit effort="100" velocity="100" k_velocity="0" />
    <joint_properties damping="0.1" friction="1.0" />
  </joint>
  <link name="link">
    <inertial>
      <mass value="10"/>
      <origin xyz="0 0 0"/>
      <inertia ixx="1.0" ixy="0.0" ixz="0.0" iyy="0.1" iyz="0.0" izz="0.1"/>
    </inertial>
    <visual>
      <origin rpy="0 0 1" xyz="0 0 0"/>
      <geometry>
        <box size="0.2 1.0 0.2"/>
      </geometry>
    </visual>
    <collision>
      <origin rpy="0 0 1" xyz="0 0 0"/>
      <geometry>
        <box size="0.2 1.0 0.2"/>
      </geometry>
    </collision>
  </link>
  <gazebo reference="link">
    <material>Gazebo/GrassFloor</material>
    <turnGravityOff>true</turnGravityOff>
  </gazebo>
  
   <gazebo>
    <controller:gazebo_ros_force name="gazebo_ros_force" plugin="libgazebo_ros_force.so">
      <alwaysOn>true</alwaysOn>
      <update>100</update>
      <updateRate>100.0</updateRate>
      <bodyName>link</bodyName>
      <topicName>force</topicName>
    </controller:gazebo_ros_force>
  </gazebo>
</robot>